<?xml version="1.0" ?>
<!-- =================================================================================== -->
<!-- |    This document was autogenerated by xacro from robot.urdf.xacro               | -->
<!-- |    EDITING THIS FILE BY HAND IS NOT RECOMMENDED                                 | -->
<!-- =================================================================================== -->
<robot name="robot">
  <gazebo>
    <!--plugin
            filename="gz-sim-pose-publisher-system"
            name="gz::sim::systems::PosePublisher">
            <publish_link_pose>true</publish_link_pose>
            <use_pose_vector_msg>true</use_pose_vector_msg>
            <static_publisher>true</static_publisher>
            <static_update_frequency>1</static_update_frequency>
        </plugin-->
    <!--plugin
            filename="gz-sim-odometry-publisher-system"
            name="gz::sim::systems::OdometryPublisher">
            <odom_frame>robot/odom</odom_frame>
            <robot_base_frame>robot/base_link</robot_base_frame>
            <odom_publish_frequency>50</odom_publish_frequency>
        </plugin-->
    <plugin filename="gz-sim-joint-state-publisher-system" name="gz::sim::systems::JointStatePublisher">
        </plugin>
    <plugin filename="gz-sim-diff-drive-system" name="gz::sim::systems::DiffDrive">
      <left_joint>left_wheel_joint</left_joint>
      <right_joint>right_wheel_joint</right_joint>
      <child_frame_id>robot/base_link</child_frame_id>
      <wheel_separation>0.291</wheel_separation>
      <wheel_radius>0.033</wheel_radius>
      <odom_publish_frequency>10</odom_publish_frequency>
    </plugin>
  </gazebo>
  <joint name="laser_joint" type="fixed">
    <parent link="base_link"/>
    <child link="laser_frame"/>
    <origin rpy="0 0 0" xyz="0.1 0 0.212"/>
  </joint>
  <link name="laser_frame">
    <visual>
      <geometry>
        <cylinder length="0.04" radius="0.05"/>
      </geometry>
      <material name="black"/>
    </visual>
    <visual>
      <origin xyz="0 0 -0.05"/>
      <geometry>
        <cylinder length="0.1" radius="0.01"/>
      </geometry>
      <material name="black"/>
    </visual>
    <collision>
      <geometry>
        <cylinder length="0.04" radius="0.05"/>
      </geometry>
    </collision>
    <inertial>
      <origin rpy="0 0 0" xyz="0 0 0"/>
      <mass value="0.1"/>
      <inertia ixx="7.583333333333335e-05" ixy="0.0" ixz="0.0" iyy="7.583333333333335e-05" iyz="0.0" izz="0.00012500000000000003"/>
    </inertial>
  </link>
  <gazebo reference="laser_frame">
    <material>Gazebo/Black</material>
    <sensor name="laser_sensor_frame" type="gpu_lidar">
      &quot;
            
      <gz_frame_id>robot/laser_frame</gz_frame_id>
      <pose> 0 0 0 0 0 0 </pose>
      <visualize>true</visualize>
      <always_on>true</always_on>
      <update_rate>10</update_rate>
      <ray>
        <scan>
          <horizontal>
            <samples>360</samples>
            <min_angle>-3.14</min_angle>
            <max_angle>3.14</max_angle>
          </horizontal>
        </scan>
        <range>
          <min>0.3</min>
          <max>12</max>
        </range>
        <noise>
          <type>gaussian</type>
          <mean>0.0</mean>
          <stddev>0.007</stddev>
        </noise>
      </ray>
    </sensor>
  </gazebo>
  <joint name="depth_joint" type="fixed">
    <parent link="base_link"/>
    <child link="depth_frame"/>
    <origin rpy="0 0.2 0" xyz="0.1 0 0.25"/>
  </joint>
  <material name="aluminum">
    <color rgba="0.5 0.5 0.5 1"/>
  </material>
  <link name="depth_frame">
    <visual>
      <origin rpy="1.5707963267948966 0 1.5707963267948966" xyz="0.00465 -0.0475 0"/>
      <geometry>
        <mesh filename="file:///home/mar/ros2_ws2/install/robot_description/share/robot_description/urdf/d455.stl" scale="0.001 0.001 0.001"/>
        <!--box size="0.026 0.124 0.029"/-->
      </geometry>
      <material name="aluminum"/>
    </visual>
    <collision>
      <origin rpy="1.5707963267948966 0 1.5707963267948966" xyz="0.00465 -0.0475 0"/>
      <geometry>
        <box size="0.026 0.124 0.029"/>
      </geometry>
    </collision>
    <inertial>
      <origin rpy="0 0 0" xyz="0 0 0"/>
      <mass value="0.116"/>
      <inertia ixx="1.4664333333333335e-05" ixy="0.0" ixz="0.0" iyy="0.00015676433333333334" iyz="0.0" izz="0.00015516933333333335"/>
    </inertial>
  </link>
  <gazebo reference="depth_frame">
    <sensor name="depth_sensor_frame" type="depth_camera">
      &quot;
            
      <gz_frame_id>robot/depth_frame</gz_frame_id>
      <pose> 0 0 0 0 0 0 </pose>
      <always_on>true</always_on>
      <update_rate>10</update_rate>
      <camera>
        <horizontal_fov>1.51843645</horizontal_fov>
        <image>
          <width>848</width>
          <height>480</height>
          <format>R_FLOAT32</format>
        </image>
        <clip>
          <near>0.1</near>
          <far>10</far>
        </clip>
        <lens>
          <intrinsics>
            <fx>421.61578369140625</fx>
            <fy>421.61578369140625</fy>
            <cx>422.2854309082031</cx>
            <cy>236.57237243652344</cy>
            <s>0</s>
          </intrinsics>
        </lens>
        <noise>
          <type>gaussian</type>
          <mean>0.0</mean>
          <stddev>0.007</stddev>
        </noise>
      </camera>
    </sensor>
    <sensor name="color_sensor_frame" type="camera">
      <gz_frame_id>robot/depth_frame</gz_frame_id>
      <pose>0 0 0 0 0 0</pose>
      <update_rate>30</update_rate>
      <always_on>true</always_on>
      <camera>
        <horizontal_fov>1.20427718</horizontal_fov>
        <image>
          <width>848</width>
          <height>480</height>
        </image>
        <clip>
          <near>0.1</near>
          <far>50</far>
        </clip>
        <lens>
          <intrinsics>
            <fx>615.9603271484375</fx>
            <fy>616.227294921875</fy>
            <cx>419.83026123046875</cx>
            <cy>245.1431427001953</cy>
            <s>0</s>
          </intrinsics>
        </lens>
      </camera>
    </sensor>
  </gazebo>
  <material name="white">
    <color rgba="1 1 1 1"/>
  </material>
  <material name="orange">
    <color rgba="1 0.3 0.1 1"/>
  </material>
  <material name="blue">
    <color rgba="0.2 0.2 1 1"/>
  </material>
  <material name="black">
    <color rgba="0 0 0 1"/>
  </material>
  <material name="red">
    <color rgba="1 0 0 1"/>
  </material>
  <link name="base_link">
    </link>
  <link name="base_footprint">
    </link>
  <joint name="base_footprint_joint" type="fixed">
    <parent link="base_link"/>
    <child link="base_footprint"/>
    <origin rpy="0 0 0" xyz="0 0 -0.138"/>
  </joint>
  <joint name="chassis_joint" type="fixed">
    <parent link="base_link"/>
    <child link="chassis"/>
    <origin xyz="-0.226 0 -0.01"/>
  </joint>
  <link name="chassis">
    <inertial>
      <origin rpy="0 0 0" xyz="0.1675 0 0.069"/>
      <mass value="1.0"/>
      <inertia ixx="0.007439083333333334" ixy="0.0" ixz="0.0" iyy="0.010939083333333335" iyz="0.0" izz="0.015204166666666668"/>
    </inertial>
    <visual>
      <origin xyz="0.1675 0 0.069"/>
      <geometry>
        <box size="0.335 0.265 0.138"/>
      </geometry>
      <material name="orange"/>
    </visual>
    <collision>
      <origin xyz="0.1675 0 0.069"/>
      <geometry>
        <box size="0.335 0.265 0.138"/>
      </geometry>
    </collision>
  </link>
  <gazebo reference="chassis">
    <material>Gazebo/Orange</material>
  </gazebo>
  <joint name="left_wheel_joint" type="continuous">
    <parent link="base_link"/>
    <child link="left_wheel"/>
    <origin rpy="-1.5707963267948966 0 0" xyz="0 0.1485 0"/>
    <axis xyz="0 0 1"/>
  </joint>
  <link name="left_wheel">
    <visual>
      <geometry>
        <cylinder length="0.026" radius="0.033"/>
      </geometry>
      <material name="blue"/>
    </visual>
    <collision>
      <geometry>
        <sphere radius="0.033"/>
      </geometry>
    </collision>
    <inertial>
      <origin rpy="0 0 0" xyz="0 0 0"/>
      <mass value="0.05"/>
      <inertia ixx="1.642916666666667e-05" ixy="0.0" ixz="0.0" iyy="1.642916666666667e-05" iyz="0.0" izz="2.7225000000000004e-05"/>
    </inertial>
  </link>
  <gazebo reference="left_wheel">
    <material>Gazebo/Blue</material>
  </gazebo>
  <joint name="right_wheel_joint" type="continuous">
    <parent link="base_link"/>
    <child link="right_wheel"/>
    <origin rpy="1.5707963267948966 0 0" xyz="0 -0.1485 0"/>
    <axis xyz="0 0 -1"/>
  </joint>
  <link name="right_wheel">
    <visual>
      <geometry>
        <cylinder length="0.026" radius="0.033"/>
      </geometry>
      <material name="blue"/>
    </visual>
    <collision>
      <geometry>
        <sphere radius="0.033"/>
      </geometry>
    </collision>
    <inertial>
      <origin rpy="0 0 0" xyz="0 0 0"/>
      <mass value="0.05"/>
      <inertia ixx="1.642916666666667e-05" ixy="0.0" ixz="0.0" iyy="1.642916666666667e-05" iyz="0.0" izz="2.7225000000000004e-05"/>
    </inertial>
  </link>
  <gazebo reference="right_wheel">
    <material>Gazebo/Blue</material>
  </gazebo>
  <joint name="caster_wheel_joint" type="fixed">
    <parent link="chassis"/>
    <child link="caster_wheel"/>
    <origin xyz="0.075 0 -0.013"/>
  </joint>
  <link name="caster_wheel">
    <visual>
      <geometry>
        <sphere radius="0.01"/>
      </geometry>
      <material name="white"/>
    </visual>
    <collision>
      <geometry>
        <sphere radius="0.01"/>
      </geometry>
    </collision>
    <inertial>
      <origin rpy="0 0 0" xyz="0 0 0"/>
      <mass value="0.01"/>
      <inertia ixx="4.0000000000000003e-07" ixy="0.0" ixz="0.0" iyy="4.0000000000000003e-07" iyz="0.0" izz="4.0000000000000003e-07"/>
    </inertial>
  </link>
  <gazebo reference="caster_wheel">
    <material>Gazebo/White</material>
    <mu1 value="0.001"/>
    <mu2 value="0.001"/>
  </gazebo>
  <link name="vasa_link">
    <visual>
      <geometry>
        <mesh filename="/home/mar/ros2_ws2/install/unique_robot/share/unique_robot/urdf/vasa.stl"/>
      </geometry>
      <material name="red"/>
    </visual>
    <!-- Остальные параметры звена, такие как инерция, масса и т.д., также могут быть указаны здесь -->
  </link>
</robot>
